Workbook

Sheet GUIA_MVP
A1: KÖRA Motor v1 (MVP)
A4: Objetivo | B4: Ordenar el motor en un flujo más claro: INPUTS → PAQUETE → MAPEO → APU → LISTA DE RECURSOS → RESUMEN.
A5: Mejoras implementadas | B5: 1) Fórmulas sin referencias duras a celdas específicas. 2) Separación entre mapeo base y APU. 3) Consolidado de recursos. 4) Resumen por EDT. 5) Hoja de control para revisión.
A6: Hojas editables | B6: Editar solo PARAMETROS (columna VALOR_PARAMETRO) y RECURSOS_PRECIOS (PRECIO_UNITARIO / FECHA / FUENTE).
A7: Hojas de lógica | B7: FORMULAS documenta reglas; PAQUETE_PK calcula cantidades; MAPEO_BASE explota cantidades a recursos; APU_DETALLE costea; LISTA_RECURSOS consolida.
A8: Criterio MVP | B8: El archivo queda listo para seguir creciendo por nuevas actividades, nuevas reglas y nuevos recursos, manteniendo trazabilidad.
A9: Convención de color | B9: Azul = inputs editables | Negro = fórmulas | Gris = catálogos / estructura | Verde = datos vinculados | Naranja = revisar.

Sheet EDT
A1: ID_EDT | B1: FASE | C1: ETAPA | D1: TIPOLOGIA | E1: UNIDAD_BASE | F1: BOQ | G1: USA_VAR_CAL | H1: USA_PK | I1: USA_APU | J1: CODIGO_PK
A2: EDT-PRE-001 | B2: PRELIMINARES | C2: SERVICIOS TEMPORALES | D2: AGUA PROVISIONAL | E2: un | F2: 1 | G2: No | H2: Si | I2: Si | J2: PK-AGUA-001
A3: EDT-PRE-002 | B3: PRELIMINARES | C3: SERVICIOS TEMPORALES | D3: ENERGIA PROVISIONAL | E3: un | F3: 1 | G3: No | H3: Si | I3: Si | J3: PK-ACOELE-001
A4: EDT-PRE-003 | B4: PRELIMINARES | C4: LIMPIEZA & NIVELACION | D4: LIMPIEZA & NIVELACION DEL TERRENO | E4: m2 | F4: 80 | G4: No | H4: Si | I4: Si | J4: PK-LN-001
A5: EDT-PRE-004 | B5: PRELIMINARES | C5: BODEGA DE OBRA | D5: BODEGA DE OBRA | E5: un | F5: 1 | G5: Si | H5: Si | I5: Si | J5: PK-BO-001
A6: EDT-PRE-005 | B6: PRELIMINARES | C6: TRAZADO | D6: TRAZADO | E6: ejes | F6: 8 | G6: No | H6: Si | I6: Si | J6: PK-TR-001
A7: EDT-FUN-001 | B7: FUNDACIONES | C7: CIMENTACION | D7: PLACA CORRIDA | E7: ml | F7: 40 | G7: Si | H7: Si | I7: Si | J7: PK-PC-001
A8: EDT-FUN-002 | B8: FUNDACIONES | C8: CIMENTACION | D8: SOBRECIMIENTO | E8: ml | F8: =F7 -> 40 | G8: Si | H8: Si | I8: Si | J8: PK-PC-002
A9: EDT-EST-001 | B9: ESTRUCTURA | C9: PAREDES | D9: MAMPOSTERIA | E9: m2 | F9: 80 | G9: Si | H9: Si | I9: Si | J9: PK-PA-001

Sheet PARAMETROS
A1: ID_EDT | B1: TIPO_PARAMETRO | C1: NOMBRE_PARAMETRO | D1: SIMBOLO_PARAMETRO | E1: VALOR_PARAMETRO | F1: UNIDAD_PARAMETRO | G1: OBSERVACIONES
A2: EDT-PRE-001 | B2: Cálculo | C2: Cantidad de Sistemas | D2: C_agua | E2: 1 | F2: un | G2: Número de sistemas o frentes de instalación
A3: EDT-PRE-001 | B3: Cálculo | C3: Longitud | D3: L_agua | E3: 20 | F3: m | G3: Longitud de tubería temporal desde el punto de abastecimiento hasta el punto de uso.
A4: EDT-PRE-001 | B4: Cálculo | C4: Numero_Puntos | D4: P_agua | E4: 3 | F4: un | G4: Número de puntos de consumo de agua en la obra
A5: EDT-PRE-001 | B5: Configuración | C5: Factor Accesorios Lineales | D5: f_lineal_agua | E5: 0.15 | F5: un/ml | G5: Factor para cálculo de figuras PVC en relación a ml de tubería
A6: EDT-PRE-001 | B6: Configuración | C6: Factor Accesorios Puntos | D6: f_puntos_agua | E6: 2 | F6: un/punto | G6: Factor para cálculo de figuras PVC en relación con puntos de consumo
A7: EDT-PRE-001 | B7: Configuración | C7: Válvulas por Punto | D7: Val_punto | E7: 0 | F7: un/punto | G7: Válvula de paso por punto de consumo
A8: EDT-PRE-002 | B8: Cálculo | C8: Cantidad de Acometidas | D8: C_elec | E8: 1 | F8: un | G8: Número de Acometidas Eléctricas (base 1)
A9: EDT-PRE-002 | B9: Cálculo | C9: Longitud de acometida | D9: L_elec | E9: 10 | F9: m | G9: Longitud de Acometida eléctrica
A10: EDT-PRE-003 | B10: Cálculo | C10: Area de Obra | D10: A_obra | E10: 1 | F10: m2 | G10: Area constructiva de la obra
A11: EDT-PRE-003 | B11: Configuración | C11: Factor de incremento de area | D11: f_area_ln | E11: 1.2 | F11: m2/m2 | G11: Factor de incremento del area para limpieza y nivelación
A12: EDT-PRE-004 | B12: Cálculo | C12: Largo de Bodega | D12: L_bodega | E12: 4 | F12: m | G12: Largo de la bodega
A13: EDT-PRE-004 | B13: Cálculo | C13: Ancho de Bodega | D13: A_bodega | E13: 3 | F13: m | G13: Ancho de la bodega
... A34: EDT-EST-001 | B34: Configuración | C34: Desperdicio de Bloque | D34: Desp_bloque | E34: 0.05 | F34: porcentaje | G34: Desperdicio de bloques concreto

Sheet VARIABLES_CALCULADAS
A1: ID_VAR_CALCULADA | B1: ID_EDT | C1: VAR_CALCULADA | D1: DESCRIPCION | E1: FORMULA_VAR_CAL | F1: CALCULO_VAR_CAL | G1: UNIDAD_VAR_CAL
A2: VAR-CAL-001 | B2: EDT-PRE-004 | C2: Area_bodega | D2: Area de la Bodega | E2: L_bodega * A_bodega | F2: =SUMIFS(PARAMETROS!$E$2:$E$199,PARAMETROS!$A$2:$A$199,B2,PARAMETROS!$D$2:$D$199,"L_bodega")*SUMIFS(PARAMETROS!$E$2:$E$199,PARAMETROS!$A$2:$A$199,B2,PARAMETROS!$D$2:$D$199,"A_bodega") -> 12 | G2: m2
A3: VAR-CAL-002 | B3: EDT-PRE-004 | C3: Perimetro_bodega | D3: Perimetro de la Bodega | E3: 2*(L_bodega + A_bodega) | F3: =2*(SUMIFS(PARAMETROS!$E$2:$E$199,PARAMETROS!$A$2:$A$199,B3,PARAMETROS!$D$2:$D$199,"L_bodega")+SUMIFS(PARAMETROS!$E$2:$E$199,PARAMETROS!$A$2:$A$199,B3,PARAMETROS!$D$2:$D$199,"A_bodega")) -> 14 | G3: m
A4: VAR-CAL-003 | B4: EDT-PRE-004 | C4: Area_pared_bodega | D4: Area de Cerramiento Bodega | E4: (2*(L_bodega + A_bodega)) * H_bodega | F4: =2*(SUMIFS(PARAMETROS!$E$2:$E$199,PARAMETROS!$A$2:$A$199,B4,PARAMETROS!$D$2:$D$199,"L_bodega")+SUMIFS(PARAMETROS!$E$2:$E$199,PARAMETROS!$A$2:$A$199,B4,PARAMETROS!$D$2:$D$199,"A_bodega"))*SUMIFS(PARAMETROS!$E$2:$E$199,PARAMETROS!$A$2:$A$199,B4,PARAMETROS!$D$2:$D$199,"H_bodega") -> 33.6 | G4: m2
A5: VAR-CAL-004 | B5: EDT-PRE-004 | C5: Area_cubierta_techo | D5: Area Cubierta Techo Bodega | E5: (L_bodega * A_bodega) * f_techo_bodega | F5: =SUMIFS(PARAMETROS!$E$2:$E$199,PARAMETROS!$A$2:$A$199,B5,PARAMETROS!$D$2:$D$199,"L_bodega")*SUMIFS(PARAMETROS!$E$2:$E$199,PARAMETROS!$A$2:$A$199,B5,PARAMETROS!$D$2:$D$199,"A_bodega")*SUMIFS(PARAMETROS!$E$2:$E$199,PARAMETROS!$A$2:$A$199,B5,PARAMETROS!$D$2:$D$199,"f_techo_bodega") -> 15 | G5: m2
A6: VAR-CAL-005 | B6: EDT-FUN-001 | C6: Area_excav | D6: Area Sección de Excavación | E6: (B_cimentación + Sobrexc_cimiento) * (Prof_cimentación +E_sello ) | F6: =(SUMIFS(PARAMETROS!$E$2:$E$199,PARAMETROS!$A$2:$A$199,B6,PARAMETROS!$D$2:$D$199,"B_cimentación")+SUMIFS(PARAMETROS!$E$2:$E$199,PARAMETROS!$A$2:$A$199,B6,PARAMETROS!$D$2:$D$199,"Sobrexc_cimiento"))*(SUMIFS(PARAMETROS!$E$2:$E$199,PARAMETROS!$A$2:$A$199,B6,PARAMETROS!$D$2:$D$199,"Prof_cimentación")+SUMIFS(PARAMETROS!$E$2:$E$199,PARAMETROS!$A$2:$A$199,B6,PARAMETROS!$D$2:$D$199,"E_sello")) -> 0.2925 | G6: m2
A7: VAR-CAL-006 | B7: EDT-FUN-001 | C7: Area_sello | D7: Area Sección de Concreto Sello | E7: E_sello * (B_cimentación + Sobrexc_cimiento) | F7: =SUMIFS(PARAMETROS!$E$2:$E$199,PARAMETROS!$A$2:$A$199,B7,PARAMETROS!$D$2:$D$199,"E_sello")*(SUMIFS(PARAMETROS!$E$2:$E$199,PARAMETROS!$A$2:$A$199,B7,PARAMETROS!$D$2:$D$199,"B_cimentación")+SUMIFS(PARAMETROS!$E$2:$E$199,PARAMETROS!$A$2:$A$199,B7,PARAMETROS!$D$2:$D$199,"Sobrexc_cimiento")) -> 0.0225 | G7: m2
A8: VAR-CAL-007 | B8: EDT-FUN-001 | C8: Area_placa | D8: Area Sección de placa | E8: (B_cimentación * H_cimentación) | F8: =SUMIFS(PARAMETROS!$E$2:$E$199,PARAMETROS!$A$2:$A$199,B8,PARAMETROS!$D$2:$D$199,"B_cimentación")*SUMIFS(PARAMETROS!$E$2:$E$199,PARAMETROS!$A$2:$A$199,B6,PARAMETROS!$D$2:$D$199,"H_cimentación") -> 0.07 | G8: m2

Sheet PAQUETE_PK
A1: CODIGO_PK | B1: ID_EDT | C1: CODIGO_ACTIVIDAD | D1: ACTIVIDAD | E1: UNIDAD | F1: FORMULA_LOGICA | G1: CANTIDAD_CALCULADA | H1: UNIDAD_PK | I1: OBSERVACIONES
A2: PK-AGUA-001 | B2: EDT-PRE-001 | C2: PK-AGUA-001-001 | D2: Acometida provisional de agua | E2: un | F2: C_agua | G2: =SUMIFS(PARAMETROS!$E$2:$E$198,PARAMETROS!$A$2:$A$198,$B2,PARAMETROS!$D$2:$D$198,"C_agua") -> 1 | H2: un | I2: Una por sistema
A3: PK-AGUA-001 | B3: EDT-PRE-001 | C3: PK-AGUA-001-002 | D3: Red temporal de agua | E3: m | F3: L_agua | G3: =SUMIFS(PARAMETROS!$E$2:$E$198,PARAMETROS!$A$2:$A$198,$B3,PARAMETROS!$D$2:$D$198,"L_agua") -> 20 | H3: m | I3: Longitud total ingresada
A4: PK-AGUA-001 | B4: EDT-PRE-001 | C4: PK-AGUA-001-003 | D4: Puntos terminales de agua | E4: un | F4: P_agua | G4: =SUMIFS(PARAMETROS!$E$2:$E$198,PARAMETROS!$A$2:$A$198,$B4,PARAMETROS!$D$2:$D$198,"P_agua") -> 3 | H4: un | I4: Puntos editables
A5: PK-AGUA-001 | B5: EDT-PRE-001 | C5: PK-AGUA-001-004 | D5: Accesorios de red | E5: un | F5: (L_agua*f_lineal_agua)+(P_agua*f_puntos_agua) | G5: =ROUNDUP(SUMIFS(PARAMETROS!$E$2:$E$198,PARAMETROS!$A$2:$A$198,$B5,PARAMETROS!$D$2:$D$198,"L_agua")*SUMIFS(PARAMETROS!$E$2:$E$198,PARAMETROS!$A$2:$A$198,$B5,PARAMETROS!$D$2:$D$198,"f_lineal_agua")+SUMIFS(PARAMETROS!$E$2:$E$198,PARAMETROS!$A$2:$A$198,$B5,PARAMETROS!$D$2:$D$198,"P_agua")*SUMIFS(PARAMETROS!$E$2:$E$198,PARAMETROS!$A$2:$A$198,$B5,PARAMETROS!$D$2:$D$198,"f_puntos_agua"),0) -> 9 | H5: un | I5: Lineales + por punto
A6: PK-AGUA-001 | B6: EDT-PRE-001 | C6: PK-AGUA-001-005 | D6: Válvulas de control | E6: un | F6: C_agua + (P_agua*Val_punto) | G6: =ROUNDUP(SUMIFS(PARAMETROS!$E$2:$E$198,PARAMETROS!$A$2:$A$198,$B6,PARAMETROS!$D$2:$D$198,"C_agua")+SUMIFS(PARAMETROS!$E$2:$E$198,PARAMETROS!$A$2:$A$198,$B6,PARAMETROS!$D$2:$D$198,"P_agua")*SUMIFS(PARAMETROS!$E$2:$E$198,PARAMETROS!$A$2:$A$198,$B6,PARAMETROS!$D$2:$D$198,"Val_punto"),0) -> 1 | H6: un | I6: Una por sistema + adicional por puntos
A7: PK-ACOELE-001 | B7: EDT-PRE-002 | C7: PK-ACOELE-001-001 | D7: Acometida eléctrica | E7: un | F7: C_elec | G7: =SUMIFS(PARAMETROS!$E$2:$E$198,PARAMETROS!$A$2:$A$198,$B7,PARAMETROS!$D$2:$D$198,"C_elec") -> 1 | H7: un | I7: Una por acometida
A8: PK-ACOELE-001 | B8: EDT-PRE-002 | C8: PK-ACOELE-001-002 | D8: Cableado de acometida | E8: m | F8: L_elec | G8: =SUMIFS(PARAMETROS!$E$2:$E$198,PARAMETROS!$A$2:$A$198,$B8,PARAMETROS!$D$2:$D$198,"L_elec") -> 10 | H8: m | I8: Longitud total de cableado
A9: PK-LN-001 | B9: EDT-PRE-003 | C9: PK-LN-001-001 | D9: Movimiento de Tierras | E9: m2 | F9: A_obra * f_area_ln | G9: =SUMIFS(PARAMETROS!$E$2:$E$198,PARAMETROS!$A$2:$A$198,$B9,PARAMETROS!$D$2:$D$198,"A_obra")*SUMIFS(PARAMETROS!$E$2:$E$198,PARAMETROS!$A$2:$A$198,$B9,PARAMETROS!$D$2:$D$198,"f_area_ln") -> 1.2 | H9: m2 | I9: Area Unitaria
A10: PK-BO-001 | B10: EDT-PRE-004 | C10: PK-BO-001-001 | D10: Estructura Soporte Bodega | E10: m | F10: Perimetro_bodega | G10: =SUMIFS(VARIABLES_CALCULADAS!$F$2:$F$198,VARIABLES_CALCULADAS!$B$2:$B$198,B10,VARIABLES_CALCULADAS!$C$2:$C$198,"Perimetro_bodega") -> 14 | H10: m | I10: Perimetro de Bodega previsto
A11: PK-BO-001 | B11: EDT-PRE-004 | C11: PK-BO-001-002 | D11: Cerramiento Lateral Bodega | E11: m2 | F11: Area_pared_bodega | G11: =SUMIFS(VARIABLES_CALCULADAS!$F$2:$F$198,VARIABLES_CALCULADAS!$B$2:$B$198,B11,VARIABLES_CALCULADAS!$C$2:$C$198,"Area_pared_bodega") -> 33.6 | H11: m2 | I11: Area de cerramiento en lamina de zinc
A12: PK-BO-001 | B12: EDT-PRE-004 | C12: PK-BO-001-003 | D12: Cubierta Techo Bodega | E12: m2 | F12: Area_cubierta_techo | G12: =SUMIFS(VARIABLES_CALCULADAS!$F$2:$F$198,VARIABLES_CALCULADAS!$B$2:$B$198,B12,VARIABLES_CALCULADAS!$C$2:$C$198,"Area_cubierta_techo") -> 15 | H12: m2 | I12: Area cubierta
A13: PK-BO-001 | B13: EDT-PRE-004 | C13: PK-BO-001-004 | D13: Puerta Acceso Bodega | E13: un | F13: Puerta_bodega | G13: =SUMIFS(PARAMETROS!$E$2:$E$198,PARAMETROS!$A$2:$A$198,$B13,PARAMETROS!$D$2:$D$198,"Puerta_bodega") -> 1 | H13: un | I13: Puerta de acceso a bodega
A14: PK-TR-001 | B14: EDT-PRE-005 | C14: PK-TR-001-001 | D14: Elaboracion e Instalación de niveleta | E14: un | F14: Num_niveleta | G14: =SUMIFS(PARAMETROS!$E$2:$E$198,PARAMETROS!$A$2:$A$198,$B14,PARAMETROS!$D$2:$D$198,"Num_niveleta") -> 2 | H14: un | I14: Niveletas por eje
A15: PK-PC-001 | B15: EDT-FUN-001 | C15: PK-PC-001-0001 | D15: Excavación Cimiento | E15: m3 | F15: Area_excav * 1 | G15: =SUMIFS(VARIABLES_CALCULADAS!$F$2:$F$198,VARIABLES_CALCULADAS!$B$2:$B$198,B15,VARIABLES_CALCULADAS!$C$2:$C$198,"Area_excav")*1 -> 0.2925 | H15: m3 | I15: m3 de excavación por m de PC
A16: PK-PC-001 | B16: EDT-FUN-001 | C16: PK-PC-001-0002 | D16: Sello de Concreto | E16: m3 | F16: Area_sello * 1 * (1+f_desp_concreto) | G16: =SUMIFS(VARIABLES_CALCULADAS!$F$2:$F$198,VARIABLES_CALCULADAS!$B$2:$B$198,B16,VARIABLES_CALCULADAS!$C$2:$C$198,"Area_sello")*1*(1+SUMIFS(PARAMETROS!$E$2:$E$198,PARAMETROS!$A$2:$A$198,$B16,PARAMETROS!$D$2:$D$198,"f_desp_concreto")) -> 0.027 | H16: m3 | I16: m3 de concreto de sello
A17: PK-PC-001 | B17: EDT-FUN-001 | C17: PK-PC-001-0003 | D17: Armadura de Placa Corrida | E17: ml | F17: (1*Q_var_long) + (1/S_ganchos) * (B_cimentación + H_cimentación- 4* E_recubrimiento) | G17: =(SUMIFS(PARAMETROS!$E$2:$E$198,PARAMETROS!$A$2:$A$198,$B17,PARAMETROS!$D$2:$D$198,"B_cimentación")+SUMIFS(PARAMETROS!$E$2:$E$198,PARAMETROS!$A$2:$A$198,$B17,PARAMETROS!$D$2:$D$198,"H_cimentación")-4*SUMIFS(PARAMETROS!$E$2:$E$198,PARAMETROS!$A$2:$A$198,$B17,PARAMETROS!$D$2:$D$198,"E_recubrimiento"))*(1/SUMIFS(PARAMETROS!$E$2:$E$198,PARAMETROS!$A$2:$A$198,$B17,PARAMETROS!$D$2:$D$198,"S_ganchos"))+(1*SUMIFS(PARAMETROS!$E$2:$E$198,PARAMETROS!$A$2:$A$198,$B17,PARAMETROS!$D$2:$D$198,"Q_var_long")) -> 4.95 | H17: ml | I17: ml de varilla #3 por ml de placa
A18: PK-PC-001 | B18: EDT-FUN-001 | C18: PK-PC-001-0004 | D18: Concreto Estructural 210kg/cm2 | E18: m3 | F18: Area_placa * 1 * (1+f_desp_concreto) | G18: =SUMIFS(VARIABLES_CALCULADAS!$F$2:$F$198,VARIABLES_CALCULADAS!$B$2:$B$198,B18,VARIABLES_CALCULADAS!$C$2:$C$198,"Area_placa")*1*(1+SUMIFS(PARAMETROS!$E$2:$E$198,PARAMETROS!$A$2:$A$198,$B18,PARAMETROS!$D$2:$D$198,"f_desp_concreto")) -> 0.084 | H18: m3 | I18: m3 de concreto por ml de placa
A19: PK-PC-002 | B19: EDT-FUN-002 | C19: PK-PC-002-0001 | D19: Area Bloques Sobrecimiento | E19: m2 | F19: H_bloques * (0,4 *0,2) * 2,5 | G19: =SUMIFS(PARAMETROS!$E$2:$E$127,PARAMETROS!$D$2:$D$127,"H_bloques")*(0.4*0.2*2.5) -> 0.4 | H19: m2 | I19: m2 de pared de bloques sobrecimientos
A20: PK-PC-002 | B20: EDT-FUN-002 | C20: PK-PC-002-0002 | D20: Acero Refuerzo | E20: ml | F20: (1 / S_acero_sobrecimiento_ver) * (H_bloques * 0,2 + 0,4) + (H_bloques * 0,2)/S_acero_hor * 1 | G20: =(1/SUMIFS(PARAMETROS!$E$2:$E$127,PARAMETROS!$D$2:$D$127,"S_acero_sobrecimiento_ver"))*SUMIFS(PARAMETROS!$E$2:$E$127,PARAMETROS!$D$2:$D$127,"H_bloques")*0.2+0.4+SUMIFS(PARAMETROS!$E$2:$E$127,PARAMETROS!$D$2:$D$127,"H_bloques")*0.2/SUMIFS(PARAMETROS!$E$2:$E$127,PARAMETROS!$D$2:$D$127,"S_acero_sobrecimiento_hor")*1 -> 2.0666667 | H20: ml | I20: ml de varilla #3 por ml de sobrecimiento
A21: PK-PC-002 | B21: EDT-FUN-002 | C21: PK-PC-002-0003 | D21: Concreto Relleno | E21: m3 | F21: (A_bloque * 0,2 * 0,85 * 5) * (H_bloques*0,2)*1,15 | G21: =SUMIFS(PARAMETROS!$E$2:$E$127,PARAMETROS!$D$2:$D$127,"A_bloque")*0.2*0.85*5 * SUMIFS(PARAMETROS!$E$2:$E$127,PARAMETROS!$D$2:$D$127,"H_bloques")*0.2*1.15 -> 0.04692 | H21: m3 | I21: m3 de concreto de relleno asuminedo toda celda rellena
A22: PK-PA-001 | B22: EDT-EST-001 | C22: PK-PA-001-0001 | D22: Bloques de Mamposteria | E22: unidades | F22: 12,5 * (1+Desp_bloque) | G22: =12.5*(1+SUMIFS(PARAMETROS!$E$2:$E$127,PARAMETROS!$D$2:$D$127,"Desp_bloque")) -> 13.125 | H22: unidades | I22: bloques por m2 de pared contemplando desperdicio
A23: PK-PA-001 | B23: EDT-EST-001 | C23: PK-PA-001-0002 | D23: Acero de Refuerzo Vertical - Horizontal | E23: ml | F23: 1/S_acero_pared_vert + 1/S_acero_pared_hor | G23: =(1/SUMIFS(PARAMETROS!$E$2:$E$127,PARAMETROS!$D$2:$D$127,"S_acero_pared_vert")) + (1/SUMIFS(PARAMETROS!$E$2:$E$127,PARAMETROS!$D$2:$D$127,"S_acero_pared_hor")) -> 4.1666667 | H23: ml | I23: ml de varilla N3 por m2 de pared de bloques
A24: PK-PA-001 | B24: EDT-EST-001 | C24: PK-PA-001-0003 | D24: Concreto de Relleno Celdas Pared | E24: m3 | F24: A_bloque_pared * 0,2 * 0,8 * (1/S_acero_pared_vert) | G24: =(SUMIFS(PARAMETROS!$E$2:$E$127,PARAMETROS!$D$2:$D$127,"A_bloque_pared")*0.2*0.8)*(1/SUMIFS(PARAMETROS!$E$2:$E$127,PARAMETROS!$D$2:$D$127,"S_acero_pared_vert")) -> 0.032 | H24: m3 | I24: m3 de concreto de relleno por m2 de pared

Sheet RENDIMIENTOS_BASE
A1: CODIGO_PK | B1: ID_EDT | C1: CODIGO_ACTIVIDAD | D1: CODIGO_APU | E1: CODIGO_RECURSO | F1: DESCRIPCION_REGLA | G1: Q_ACTIVIDAD | H1: FACTOR_RECURSO | I1: UNIDAD_FACTOR | J1: QYT_APU | K1: OBSERVACIONES
A2: PK-AGUA-001 | B2: EDT-PRE-001 | C2: PK-AGUA-001-001 | D2: APU-AGUA-001 | E2: 1 | F2: Acometida agua x 1 unión tope | G2: =SUMIFS(PAQUETE_PK!$G$2:$G$198,PAQUETE_PK!$C$2:$C$198,$C2) -> 1 | H2: 1 | I2: un/un | J2: =G2*H2 -> 1 | K2: Uno por sistema
A3: PK-AGUA-001 | B3: EDT-PRE-001 | C3: PK-AGUA-001-001 | D3: APU-AGUA-001 | E3: 2 | F3: Acometida agua x 1 válvula bola | G3: =SUMIFS(PAQUETE_PK!$G$2:$G$198,PAQUETE_PK!$C$2:$C$198,$C3) -> 1 | H3: 1 | I3: un/un | J3: =G3*H3 -> 1 | K3: Uno por sistema
A4: PK-AGUA-001 | B4: EDT-PRE-001 | C4: PK-AGUA-001-002 | D4: APU-AGUA-001 | E4: 3 | F4: Red agua / 6 m por tubo | G4: =SUMIFS(PAQUETE_PK!$G$2:$G$198,PAQUETE_PK!$C$2:$C$198,$C4) -> 20 | H4: 0.16666667 | I4: un/m | J4: =G4*H4 -> 3.3333333 | K4: Tubo comercial de 6m
A5: PK-AGUA-001 | B5: EDT-PRE-001 | C5: PK-AGUA-001-003 | D5: APU-AGUA-001 | E5: 4 | F5: Punto terminal x 1 llave | G5: =SUMIFS(PAQUETE_PK!$G$2:$G$198,PAQUETE_PK!$C$2:$C$198,$C5) -> 3 | H5: 1 | I5: un/un | J5: =G5*H5 -> 3 | K5: Uno por punto
A6: PK-AGUA-001 | B6: EDT-PRE-001 | C6: PK-AGUA-001-004 | D6: APU-AGUA-001 | E6: 5 | F6: Accesorios x 70% codos | G6: =SUMIFS(PAQUETE_PK!$G$2:$G$198,PAQUETE_PK!$C$2:$C$198,$C6) -> 9 | H6: 0.7 | I6: un/un | J6: =G6*H6 -> 6.3 | K6: Distribución estimada
A7: PK-AGUA-001 | B7: EDT-PRE-001 | C7: PK-AGUA-001-004 | D7: APU-AGUA-001 | E7: 6 | F7: Accesorios x 30% tees | G7: =SUMIFS(PAQUETE_PK!$G$2:$G$198,PAQUETE_PK!$C$2:$C$198,$C7) -> 9 | H7: 0.3 | I7: un/un | J7: =G7*H7 -> 2.7 | K7: Distribución estimada
A8: PK-AGUA-001 | B8: EDT-PRE-001 | C8: PK-AGUA-001-005 | D8: APU-AGUA-001 | E8: 7 | F8: Válvulas control x 1 | G8: =SUMIFS(PAQUETE_PK!$G$2:$G$198,PAQUETE_PK!$C$2:$C$198,$C8) -> 1 | H8: 1 | I8: un/un | J8: =G8*H8 -> 1 | K8: Una por sistema o punto
A9: PK-AGUA-001 | B9: EDT-PRE-001 | C9: PK-AGUA-001-001 | D9: APU-AGUA-001 | E9: 8 | F9: Operario HH por acometida | G9: =SUMIFS(PAQUETE_PK!$G$2:$G$198,PAQUETE_PK!$C$2:$C$198,$C9) -> 1 | H9: 4.5 | I9: hr/un | J9: =G9*H9 -> 4.5 | K9: Rendimiento preliminar
A10: PK-AGUA-001 | B10: EDT-PRE-001 | C10: PK-AGUA-001-001 | D10: APU-AGUA-001 | E10: 10 | F10: Peón HH por acometida | G10: =SUMIFS(PAQUETE_PK!$G$2:$G$198,PAQUETE_PK!$C$2:$C$198,$C10) -> 1 | H10: 4.5 | I10: hr/un | J10: =G10*H10 -> 4.5 | K10: Rendimiento preliminar
A11: PK-ACOELE-001 | B11: EDT-PRE-002 | C11: PK-ACOELE-001-001 | D11: APU-ACOELE-001 | E11: 11 | F11: Acometida eléctrica x 1 conduleta | G11: =SUMIFS(PAQUETE_PK!$G$2:$G$198,PAQUETE_PK!$C$2:$C$198,$C11) -> 1 | H11: 1 | I11: un/un | J11: =G11*H11 -> 1 | K11: Uno por acometida
A12: PK-ACOELE-001 | B12: EDT-PRE-002 | C12: PK-ACOELE-001-001 | D12: APU-ACOELE-001 | E12: 12 | F12: Acometida eléctrica x 1 tubo HG | G12: =SUMIFS(PAQUETE_PK!$G$2:$G$198,PAQUETE_PK!$C$2:$C$198,$C12) -> 1 | H12: 1 | I12: un/un | J12: =G12*H12 -> 1 | K12: Uno por acometida
A13: PK-ACOELE-001 | B13: EDT-PRE-002 | C13: PK-ACOELE-001-001 | D13: APU-ACOELE-001 | E13: 13 | F13: Acometida eléctrica x 1 base medidor | G13: =SUMIFS(PAQUETE_PK!$G$2:$G$198,PAQUETE_PK!$C$2:$C$198,$C13) -> 1 | H13: 1 | I13: un/un | J13: =G13*H13 -> 1 | K13: Uno por acometida
... A22: PK-ACOELE-001 | B22: EDT-PRE-002 | C22: PK-ACOELE-001-001 | D22: APU-ACOELE-001 | E22: 10 | F22: Peón HH por acometida | G22: =SUMIFS(PAQUETE_PK!$G$2:$G$198,PAQUETE_PK!$C$2:$C$198,$C22) -> 1 | H22: 5 | I22: hr/un | J22: =G22*H22 -> 5 | K22: Rendimiento preliminar
A23: PK-LN-001 | B23: EDT-PRE-003 | C23: PK-LN-001-001 | D23: APU-LN-001 | E23: 21 | F23: Rendimiento unitario de back hoe m2 | G23: =SUMIFS(PAQUETE_PK!$G$2:$G$198,PAQUETE_PK!$C$2:$C$198,$C23) -> 1.2 | H23: =8/200 -> 0.04 | I23: hr/m2 | J23: =G23*H23 -> 0.048 | K23: Se calcula con base en 8 horas para casa de 200m2
A24: PK-BO-001 | B24: EDT-PRE-004 | C24: PK-BO-001-001 | D24: APU-BO-001-001 | E24: 22 | F24: Postes por m de perimetro de bodega @1,2m | G24: =SUMIFS(PAQUETE_PK!$G$2:$G$198,PAQUETE_PK!$C$2:$C$198,$C24) -> 14 | H24: =1/1.2 -> 0.83333333 | I24: postes/m | J24: =G24*H24 -> 11.666667 | K24: Estimación postes @1,2cm
A25: PK-BO-001 | B25: EDT-PRE-004 | C25: PK-BO-001-001 | D25: APU-BO-001-001 | E25: 23 | F25: Viga Madera inferior y superior | G25: =SUMIFS(PAQUETE_PK!$G$2:$G$198,PAQUETE_PK!$C$2:$C$198,$C25) -> 14 | H25: =2/3.2 -> 0.625 | I25: un/m | J25: =G25*H25 -> 8.75 | K25: Estimación inicial
A26: PK-BO-001 | B26: EDT-PRE-004 | C26: PK-BO-001-002 | D26: APU-BO-001-002 | E26: 23 | F26: Regla Refuerzo Lateral | G26: =SUMIFS(PAQUETE_PK!$G$2:$G$198,PAQUETE_PK!$C$2:$C$198,$C26) -> 33.6 | H26: 0.2 | I26: un/m | J26: =G26*H26 -> 6.72
A27: PK-BO-001 | B27: EDT-PRE-004 | C27: PK-BO-001-002 | D27: APU-BO-001-002 | E27: 24 | F27: Lamina por m2 | G27: =SUMIFS(PAQUETE_PK!$G$2:$G$198,PAQUETE_PK!$C$2:$C$198,$C27) -> 33.6 | H27: =1/(2.44*0.81) -> 0.50597045 | I27: lam/m2 | J27: =G27*H27 -> 17.000607
A28: PK-BO-001 | B28: EDT-PRE-004 | C28: PK-BO-001-002 | D28: APU-BO-001-002 | E28: 25 | F28: Cantidad por m2 | G28: =SUMIFS(PAQUETE_PK!$G$2:$G$198,PAQUETE_PK!$C$2:$C$198,$C28) -> 33.6 | H28: 12 | I28: un/m2 | J28: =G28*H28 -> 403.2
A29: PK-BO-001 | B29: EDT-PRE-004 | C29: PK-BO-001-003 | D29: APU-BO-001-003 | E29: 23 | F29: Clavadores @80cm | G29: =SUMIFS(PAQUETE_PK!$G$2:$G$198,PAQUETE_PK!$C$2:$C$198,$C29) -> 15 | H29: =1/0.8/3.2 -> 0.390625 | I29: un/m | J29: =G29*H29 -> 5.859375
A30: PK-BO-001 | B30: EDT-PRE-004 | C30: PK-BO-001-003 | D30: APU-BO-001-003 | E30: 24 | F30: Lamina por m2 | G30: =SUMIFS(PAQUETE_PK!$G$2:$G$198,PAQUETE_PK!$C$2:$C$198,$C30) -> 15 | H30: 0.51 | I30: lam/m2 | J30: =G30*H30 -> 7.65
A31: PK-BO-001 | B31: EDT-PRE-004 | C31: PK-BO-001-003 | D31: APU-BO-001-003 | E31: 25 | F31: Cantidad por m2 | G31: =SUMIFS(PAQUETE_PK!$G$2:$G$198,PAQUETE_PK!$C$2:$C$198,$C31) -> 15 | H31: 15 | I31: un/m2 | J31: =G31*H31 -> 225
A32: PK-BO-001 | B32: EDT-PRE-004 | C32: PK-BO-001-004 | D32: APU-BO-001-004 | E32: 24 | F32: Puerta del tamaño completo de lamina | G32: =SUMIFS(PAQUETE_PK!$G$2:$G$198,PAQUETE_PK!$C$2:$C$198,$C32) -> 1 | H32: 1 | I32: lam/un | J32: =G32*H32 -> 1
A33: PK-BO-001 | B33: EDT-PRE-004 | C33: PK-BO-001-004 | D33: APU-BO-001-004 | E33: 23 | F33: Marco Madera solo Vertical | G33: =SUMIFS(PAQUETE_PK!$G$2:$G$198,PAQUETE_PK!$C$2:$C$198,$C33) -> 1 | H33: =2*2.44/3.2 -> 1.525 | I33: un/un | J33: =G33*H33 -> 1.525
A34: PK-BO-001 | B34: EDT-PRE-004 | C34: PK-BO-001-004 | D34: APU-BO-001-004 | E34: 26 | F34: un par por puerta | G34: =SUMIFS(PAQUETE_PK!$G$2:$G$198,PAQUETE_PK!$C$2:$C$198,$C34) -> 1 | H34: 1 | I34: un/un | J34: =G34*H34 -> 1
A35: PK-BO-001 | B35: EDT-PRE-004 | C35: PK-BO-001-004 | D35: APU-BO-001-004 | E35: 27 | F35: uno por puerta | G35: =SUMIFS(PAQUETE_PK!$G$2:$G$198,PAQUETE_PK!$C$2:$C$198,$C35) -> 1 | H35: 1 | I35: un/un | J35: =G35*H35 -> 1
A36: PK-BO-001 | B36: EDT-PRE-004 | C36: PK-BO-001-004 | D36: APU-BO-001-004 | E36: 28 | F36: 1 m por puerta | G36: =SUMIFS(PAQUETE_PK!$G$2:$G$198,PAQUETE_PK!$C$2:$C$198,$C36) -> 1 | H36: 1 | I36: m/un | J36: =G36*H36 -> 1
A37: PK-BO-001 | B37: EDT-PRE-004 | C37: PK-BO-001-004 | D37: APU-BO-001-004 | E37: 8 | F37: Operario HH Bodega | G37: =SUMIFS(PAQUETE_PK!$G$2:$G$198,PAQUETE_PK!$C$2:$C$198,$C37) -> 1 | H37: 4 | I37: hr/un | J37: =G37*H37 -> 4
A38: PK-BO-001 | B38: EDT-PRE-004 | C38: PK-BO-001-004 | D38: APU-BO-001-004 | E38: 9 | F38: Ayudante HH Bodega | G38: =SUMIFS(PAQUETE_PK!$G$2:$G$198,PAQUETE_PK!$C$2:$C$198,$C38) -> 1 | H38: 4 | I38: hr/un | J38: =G38*H38 -> 4
A39: PK-BO-001 | B39: EDT-PRE-004 | C39: PK-BO-001-004 | D39: APU-BO-001-004 | E39: 10 | F39: Peón HH por bodega | G39: =SUMIFS(PAQUETE_PK!$G$2:$G$198,PAQUETE_PK!$C$2:$C$198,$C39) -> 1 | H39: 4 | I39: hr/un | J39: =G39*H39 -> 4
A40: PK-TR-001 | B40: EDT-PRE-005 | C40: PK-TR-001-001 | D40: APU-TR-001-001 | E40: 23 | F40: se pasa de ml por eje a unidad por eje | G40: =SUMIFS(PAQUETE_PK!$G$2:$G$198,PAQUETE_PK!$C$2:$C$198,$C40) -> 2 | H40: =(1.2+0.6+0.6+0.6)/3.2 -> 0.9375 | I40: un/eje | J40: =G40*H40 -> 1.875
A41: PK-TR-001 | B41: EDT-PRE-005 | C41: PK-TR-001-001 | D41: APU-TR-001-001 | E41: 8 | F41: Operario HH | G41: =SUMIFS(PAQUETE_PK!$G$2:$G$198,PAQUETE_PK!$C$2:$C$198,$C41) -> 2 | H41: 0.3 | I41: hr/eje | J41: =G41*H41 -> 0.6
A42: PK-TR-001 | B42: EDT-PRE-005 | C42: PK-TR-001-001 | D42: APU-TR-001-001 | E42: 9 | F42: Ayudante HH | G42: =SUMIFS(PAQUETE_PK!$G$2:$G$198,PAQUETE_PK!$C$2:$C$198,$C42) -> 2 | H42: 0.3 | I42: hr/eje | J42: =G42*H42 -> 0.6
A43: PK-TR-001 | B43: EDT-PRE-005 | C43: PK-TR-001-001 | D43: APU-TR-001-001 | E43: 10 | F43: Peon HH | G43: =SUMIFS(PAQUETE_PK!$G$2:$G$198,PAQUETE_PK!$C$2:$C$198,$C43) -> 2 | H43: 0.3 | I43: hr/eje | J43: =G43*H43 -> 0.6
A44: PK-PC-001 | B44: EDT-FUN-001 | C44: PK-PC-001-0001 | D44: APU-PC-001-0001 | E44: 21 | F44: Excavación con back hoe balde de 40cm | G44: =SUMIFS(PAQUETE_PK!$G$2:$G$198,PAQUETE_PK!$C$2:$C$198,$C44) -> 0.2925 | H44: 1 | I44: hr/m3 | J44: =G44*H44 -> 0.2925
A45: PK-PC-001 | B45: EDT-FUN-001 | C45: PK-PC-001-0002 | D45: APU-PC-001-0002 | E45: 29 | F45: Arena por m3 de concreto 105 kg/cm2 | G45: =SUMIFS(PAQUETE_PK!$G$2:$G$198,PAQUETE_PK!$C$2:$C$198,$C45) -> 0.027 | H45: 0.486 | I45: m3/m3 | J45: =G45*H45 -> 0.013122
A46: PK-PC-001 | B46: EDT-FUN-001 | C46: PK-PC-001-0002 | D46: APU-PC-001-0002 | E46: 30 | F46: Piedra por m3 de concreto 105 kg/cm2 | G46: =SUMIFS(PAQUETE_PK!$G$2:$G$198,PAQUETE_PK!$C$2:$C$198,$C46) -> 0.027 | H46: 0.927 | I46: m3/m3 | J46: =G46*H46 -> 0.025029
A47: PK-PC-001 | B47: EDT-FUN-001 | C47: PK-PC-001-0002 | D47: APU-PC-001-0002 | E47: 31 | F47: Sacos Cemento por m3 de concreto 105 kg/cm2 | G47: =SUMIFS(PAQUETE_PK!$G$2:$G$198,PAQUETE_PK!$C$2:$C$198,$C47) -> 0.027 | H47: 4.4 | I47: sacos/m3 | J47: =G47*H47 -> 0.1188
A48: PK-PC-001 | B48: EDT-FUN-001 | C48: PK-PC-001-0002 | D48: APU-PC-001-0002 | E48: 8 | F48: Operario HH Concreto Sello | G48: =SUMIFS(PAQUETE_PK!$G$2:$G$198,PAQUETE_PK!$C$2:$C$198,$C48) -> 0.027 | H48: 1.46 | I48: HH/m3 | J48: =G48*H48 -> 0.03942 | K48: Fuente Pag 8 Presupuesto CUNA
...

Sheet RECURSOS_PRECIOS
A1: CODIGO_RECURSO | B1: NOMBRE_RECURSO | C1: TIPO_RECURSO | D1: UNIDAD_RECURSO | E1: PRECIO_UNITARIO | F1: FUENTE | G1: FECHA | H1: OBSERVACIONES
A2: 1 | B2: Unión de Tope 1/2" PVC | C2: Material | D2: un | E2: 1 | F2: mercado | G2: 46106
A3: 2 | B3: Valvula Bola PVC 1/2" | C3: Material | D3: un | E3: 2 | F3: mercado | G3: 46106
A4: 3 | B4: Tubo PVC 1/2" | C4: Material | D4: un | E4: 10 | F4: mercado | G4: 46106
A5: 4 | B5: Llave de Chorro | C5: Material | D5: un | E5: 22 | F5: mercado | G5: 46106
A6: 5 | B6: Codo 90° 1/2" PVC | C6: Material | D6: un | E6: 4 | F6: mercado | G6: 46106
A7: 6 | B7: Tee 1/2" PVC | C7: Material | D7: un | E7: 4.5 | F7: mercado | G7: 46106
A8: 7 | B8: Valvula de Control | C8: Material | D8: un | E8: 12 | F8: mercado | G8: 46106
A9: 8 | B9: Operario | C9: Mano Obra | D9: hr | E9: 6 | F9: mercado | G9: 46106
A10: 9 | B10: Ayudante | C10: Mano Obra | D10: hr | E10: 5 | F10: mercado | G10: 46106
A11: 10 | B11: Peon | C11: Mano Obra | D11: hr | E11: 4 | F11: mercado | G11: 46106
A12: 11 | B12: Conduleta Botagua 1 1/2" | C12: Material | D12: un | E12: 35 | F12: mercado | G12: 46106
A13: 12 | B13: Tubo HG 1 1/2" | C13: Material | D13: un | E13: 25 | F13: mercado | G13: 46106
... A36: 35 | B36: Mortero Pega Bloque | C36: Material | D36: un | E36: 5.8 | F36: mercado | G36: 46102

Sheet APU_DETALLE
A1: CODIGO_APU | B1: ID_EDT | C1: CODIGO_ACTIVIDAD | D1: CODIGO_RECURSO | E1: TIPO_RECURSO | F1: RECURSO | G1: UNIDAD_RECURSO | H1: QYT_APU | I1: PRECIO_UNITARIO | J1: COSTO_APU | K1: FUENTE
A2: =RENDIMIENTOS_BASE!D2 -> APU-AGUA-001 | B2: =RENDIMIENTOS_BASE!B2 -> EDT-PRE-001 | C2: =RENDIMIENTOS_BASE!C2 -> PK-AGUA-001-001 | D2: =RENDIMIENTOS_BASE!E2 -> 1 | E2: =VLOOKUP(D2,RECURSOS_PRECIOS!$A$2:$H$201,3,FALSE) -> Material | F2: =VLOOKUP(D2,RECURSOS_PRECIOS!$A$2:$H$201,2,FALSE) -> Unión de Tope 1/2" PVC | G2: =VLOOKUP(D2,RECURSOS_PRECIOS!$A$2:$H$201,4,FALSE) -> un | H2: =RENDIMIENTOS_BASE!J2 -> 1 | I2: =VLOOKUP(D2,RECURSOS_PRECIOS!$A$2:$H$201,5,FALSE) -> 1 | J2: =H2*I2 -> 1 | K2: =VLOOKUP(D2,RECURSOS_PRECIOS!$A$2:$H$201,6,FALSE) -> mercado
A3: =RENDIMIENTOS_BASE!D3 -> APU-AGUA-001 | B3: =RENDIMIENTOS_BASE!B3 -> EDT-PRE-001 | C3: =RENDIMIENTOS_BASE!C3 -> PK-AGUA-001-001 | D3: =RENDIMIENTOS_BASE!E3 -> 2 | E3: =VLOOKUP(D3,RECURSOS_PRECIOS!$A$2:$H$201,3,FALSE) -> Material | F3: =VLOOKUP(D3,RECURSOS_PRECIOS!$A$2:$H$201,2,FALSE) -> Valvula Bola PVC 1/2" | G3: =VLOOKUP(D3,RECURSOS_PRECIOS!$A$2:$H$201,4,FALSE) -> un | H3: =RENDIMIENTOS_BASE!J3 -> 1 | I3: =VLOOKUP(D3,RECURSOS_PRECIOS!$A$2:$H$201,5,FALSE) -> 2 | J3: =H3*I3 -> 2 | K3: =VLOOKUP(D3,RECURSOS_PRECIOS!$A$2:$H$201,6,FALSE) -> mercado
A4: =RENDIMIENTOS_BASE!D4 -> APU-AGUA-001 | B4: =RENDIMIENTOS_BASE!B4 -> EDT-PRE-001 | C4: =RENDIMIENTOS_BASE!C4 -> PK-AGUA-001-002 | D4: =RENDIMIENTOS_BASE!E4 -> 3 | E4: =VLOOKUP(D4,RECURSOS_PRECIOS!$A$2:$H$201,3,FALSE) -> Material | F4: =VLOOKUP(D4,RECURSOS_PRECIOS!$A$2:$H$201,2,FALSE) -> Tubo PVC 1/2" | G4: =VLOOKUP(D4,RECURSOS_PRECIOS!$A$2:$H$201,4,FALSE) -> un | H4: =RENDIMIENTOS_BASE!J4 -> 3.3333333 | I4: =VLOOKUP(D4,RECURSOS_PRECIOS!$A$2:$H$201,5,FALSE) -> 10 | J4: =H4*I4 -> 33.333333 | K4: =VLOOKUP(D4,RECURSOS_PRECIOS!$A$2:$H$201,6,FALSE) -> mercado
A5: =RENDIMIENTOS_BASE!D5 -> APU-AGUA-001 | B5: =RENDIMIENTOS_BASE!B5 -> EDT-PRE-001 | C5: =RENDIMIENTOS_BASE!C5 -> PK-AGUA-001-003 | D5: =RENDIMIENTOS_BASE!E5 -> 4 | E5: =VLOOKUP(D5,RECURSOS_PRECIOS!$A$2:$H$201,3,FALSE) -> Material | F5: =VLOOKUP(D5,RECURSOS_PRECIOS!$A$2:$H$201,2,FALSE) -> Llave de Chorro | G5: =VLOOKUP(D5,RECURSOS_PRECIOS!$A$2:$H$201,4,FALSE) -> un | H5: =RENDIMIENTOS_BASE!J5 -> 3 | I5: =VLOOKUP(D5,RECURSOS_PRECIOS!$A$2:$H$201,5,FALSE) -> 22 | J5: =H5*I5 -> 66 | K5: =VLOOKUP(D5,RECURSOS_PRECIOS!$A$2:$H$201,6,FALSE) -> mercado
A6: =RENDIMIENTOS_BASE!D6 -> APU-AGUA-001 | B6: =RENDIMIENTOS_BASE!B6 -> EDT-PRE-001 | C6: =RENDIMIENTOS_BASE!C6 -> PK-AGUA-001-004 | D6: =RENDIMIENTOS_BASE!E6 -> 5 | E6: =VLOOKUP(D6,RECURSOS_PRECIOS!$A$2:$H$201,3,FALSE) -> Material | F6: =VLOOKUP(D6,RECURSOS_PRECIOS!$A$2:$H$201,2,FALSE) -> Codo 90° 1/2" PVC | G6: =VLOOKUP(D6,RECURSOS_PRECIOS!$A$2:$H$201,4,FALSE) -> un | H6: =RENDIMIENTOS_BASE!J6 -> 6.3 | I6: =VLOOKUP(D6,RECURSOS_PRECIOS!$A$2:$H$201,5,FALSE) -> 4 | J6: =H6*I6 -> 25.2 | K6: =VLOOKUP(D6,RECURSOS_PRECIOS!$A$2:$H$201,6,FALSE) -> mercado
A7: =RENDIMIENTOS_BASE!D7 -> APU-AGUA-001 | B7: =RENDIMIENTOS_BASE!B7 -> EDT-PRE-001 | C7: =RENDIMIENTOS_BASE!C7 -> PK-AGUA-001-004 | D7: =RENDIMIENTOS_BASE!E7 -> 6 | E7: =VLOOKUP(D7,RECURSOS_PRECIOS!$A$2:$H$201,3,FALSE) -> Material | F7: =VLOOKUP(D7,RECURSOS_PRECIOS!$A$2:$H$201,2,FALSE) -> Tee 1/2" PVC | G7: =VLOOKUP(D7,RECURSOS_PRECIOS!$A$2:$H$201,4,FALSE) -> un | H7: =RENDIMIENTOS_BASE!J7 -> 2.7 | I7: =VLOOKUP(D7,RECURSOS_PRECIOS!$A$2:$H$201,5,FALSE) -> 4.5 | J7: =H7*I7 -> 12.15 | K7: =VLOOKUP(D7,RECURSOS_PRECIOS!$A$2:$H$201,6,FALSE) -> mercado
A8: =RENDIMIENTOS_BASE!D8 -> APU-AGUA-001 | B8: =RENDIMIENTOS_BASE!B8 -> EDT-PRE-001 | C8: =RENDIMIENTOS_BASE!C8 -> PK-AGUA-001-005 | D8: =RENDIMIENTOS_BASE!E8 -> 7 | E8: =VLOOKUP(D8,RECURSOS_PRECIOS!$A$2:$H$201,3,FALSE) -> Material | F8: =VLOOKUP(D8,RECURSOS_PRECIOS!$A$2:$H$201,2,FALSE) -> Valvula de Control | G8: =VLOOKUP(D8,RECURSOS_PRECIOS!$A$2:$H$201,4,FALSE) -> un | H8: =RENDIMIENTOS_BASE!J8 -> 1 | I8: =VLOOKUP(D8,RECURSOS_PRECIOS!$A$2:$H$201,5,FALSE) -> 12 | J8: =H8*I8 -> 12 | K8: =VLOOKUP(D8,RECURSOS_PRECIOS!$A$2:$H$201,6,FALSE) -> mercado
A9: =RENDIMIENTOS_BASE!D9 -> APU-AGUA-001 | B9: =RENDIMIENTOS_BASE!B9 -> EDT-PRE-001 | C9: =RENDIMIENTOS_BASE!C9 -> PK-AGUA-001-001 | D9: =RENDIMIENTOS_BASE!E9 -> 8 | E9: =VLOOKUP(D9,RECURSOS_PRECIOS!$A$2:$H$201,3,FALSE) -> Mano Obra | F9: =VLOOKUP(D9,RECURSOS_PRECIOS!$A$2:$H$201,2,FALSE) -> Operario | G9: =VLOOKUP(D9,RECURSOS_PRECIOS!$A$2:$H$201,4,FALSE) -> hr | H9: =RENDIMIENTOS_BASE!J9 -> 4.5 | I9: =VLOOKUP(D9,RECURSOS_PRECIOS!$A$2:$H$201,5,FALSE) -> 6 | J9: =H9*I9 -> 27 | K9: =VLOOKUP(D9,RECURSOS_PRECIOS!$A$2:$H$201,6,FALSE) -> mercado
A10: =RENDIMIENTOS_BASE!D10 -> APU-AGUA-001 | B10: =RENDIMIENTOS_BASE!B10 -> EDT-PRE-001 | C10: =RENDIMIENTOS_BASE!C10 -> PK-AGUA-001-001 | D10: =RENDIMIENTOS_BASE!E10 -> 10 | E10: =VLOOKUP(D10,RECURSOS_PRECIOS!$A$2:$H$201,3,FALSE) -> Mano Obra | F10: =VLOOKUP(D10,RECURSOS_PRECIOS!$A$2:$H$201,2,FALSE) -> Peon | G10: =VLOOKUP(D10,RECURSOS_PRECIOS!$A$2:$H$201,4,FALSE) -> hr | H10: =RENDIMIENTOS_BASE!J10 -> 4.5 | I10: =VLOOKUP(D10,RECURSOS_PRECIOS!$A$2:$H$201,5,FALSE) -> 4 | J10: =H10*I10 -> 18 | K10: =VLOOKUP(D10,RECURSOS_PRECIOS!$A$2:$H$201,6,FALSE) -> mercado
A11: =RENDIMIENTOS_BASE!D11 -> APU-ACOELE-001 | B11: =RENDIMIENTOS_BASE!B11 -> EDT-PRE-002 | C11: =RENDIMIENTOS_BASE!C11 -> PK-ACOELE-001-001 | D11: =RENDIMIENTOS_BASE!E11 -> 11 | E11: =VLOOKUP(D11,RECURSOS_PRECIOS!$A$2:$H$201,3,FALSE) -> Material | F11: =VLOOKUP(D11,RECURSOS_PRECIOS!$A$2:$H$201,2,FALSE) -> Conduleta Botagua 1 1/2" | G11: =VLOOKUP(D11,RECURSOS_PRECIOS!$A$2:$H$201,4,FALSE) -> un | H11: =RENDIMIENTOS_BASE!J11 -> 1 | I11: =VLOOKUP(D11,RECURSOS_PRECIOS!$A$2:$H$201,5,FALSE) -> 35 | J11: =H11*I11 -> 35 | K11: =VLOOKUP(D11,RECURSOS_PRECIOS!$A$2:$H$201,6,FALSE) -> mercado
A12: =RENDIMIENTOS_BASE!D12 -> APU-ACOELE-001 | B12: =RENDIMIENTOS_BASE!B12 -> EDT-PRE-002 | C12: =RENDIMIENTOS_BASE!C12 -> PK-ACOELE-001-001 | D12: =RENDIMIENTOS_BASE!E12 -> 12 | E12: =VLOOKUP(D12,RECURSOS_PRECIOS!$A$2:$H$201,3,FALSE) -> Material | F12: =VLOOKUP(D12,RECURSOS_PRECIOS!$A$2:$H$201,2,FALSE) -> Tubo HG 1 1/2" | G12: =VLOOKUP(D12,RECURSOS_PRECIOS!$A$2:$H$201,4,FALSE) -> un | H12: =RENDIMIENTOS_BASE!J12 -> 1 | I12: =VLOOKUP(D12,RECURSOS_PRECIOS!$A$2:$H$201,5,FALSE) -> 25 | J12: =H12*I12 -> 25 | K12: =VLOOKUP(D12,RECURSOS_PRECIOS!$A$2:$H$201,6,FALSE) -> mercado
A13: =RENDIMIENTOS_BASE!D13 -> APU-ACOELE-001 | B13: =RENDIMIENTOS_BASE!B13 -> EDT-PRE-002 | C13: =RENDIMIENTOS_BASE!C13 -> PK-ACOELE-001-001 | D13: =RENDIMIENTOS_BASE!E13 -> 13 | E13: =VLOOKUP(D13,RECURSOS_PRECIOS!$A$2:$H$201,3,FALSE) -> Material | F13: =VLOOKUP(D13,RECURSOS_PRECIOS!$A$2:$H$201,2,FALSE) -> Base de Medidor | G13: =VLOOKUP(D13,RECURSOS_PRECIOS!$A$2:$H$201,4,FALSE) -> un | H13: =RENDIMIENTOS_BASE!J13 -> 1 | I13: =VLOOKUP(D13,RECURSOS_PRECIOS!$A$2:$H$201,5,FALSE) -> 45 | J13: =H13*I13 -> 45 | K13: =VLOOKUP(D13,RECURSOS_PRECIOS!$A$2:$H$201,6,FALSE) -> mercado
... A65: =RENDIMIENTOS_BASE!D65 -> APU-PC-002-0001 | B65: =RENDIMIENTOS_BASE!B65 -> EDT-FUN-002 | C65: =RENDIMIENTOS_BASE!C65 -> PK-PC-002-0001 | D65: =RENDIMIENTOS_BASE!E65 -> 10 | E65: =VLOOKUP(D65,RECURSOS_PRECIOS!$A$2:$H$201,3,FALSE) -> Mano Obra | F65: =VLOOKUP(D65,RECURSOS_PRECIOS!$A$2:$H$201,2,FALSE) -> Peon | G65: =VLOOKUP(D65,RECURSOS_PRECIOS!$A$2:$H$201,4,FALSE) -> hr | H65: =RENDIMIENTOS_BASE!J65 -> 0.188 | I65: =VLOOKUP(D65,RECURSOS_PRECIOS!$A$2:$H$201,5,FALSE) -> 4 | J65: =H65*I65 -> 0.752 | K65: =VLOOKUP(D65,RECURSOS_PRECIOS!$A$2:$H$201,6,FALSE) -> mercado

Sheet RESUMEN_EDT
A1: ID_EDT | B1: FASE | C1: ETAPA | D1: TIPOLOGIA | E1: UNIDAD | F1: BOQ | G1: APU_MATERIAL | H1: APU_MO | I1: APU_SUBCONTRATO | J1: APU_TOTAL | K1: SUBTOTAL_MATERIALES | L1: SUBTOTAL_MO | M1: SUBTOTAL_SUBCONTRATO | N1: SUBTOTAL
A2: =EDT!A2 -> EDT-PRE-001 | B2: =EDT!B2 -> PRELIMINARES | C2: =EDT!C2 -> SERVICIOS TEMPORALES | D2: =EDT!D2 -> AGUA PROVISIONAL | E2: =EDT!E2 -> un | F2: =EDT!F2 -> 1 | G2: =SUMIFS(APU_DETALLE!$J$2:$J$194,APU_DETALLE!$B$2:$B$194,$A2,APU_DETALLE!$E$2:$E$194,"Material") -> 151.68333 | H2: =SUMIFS(APU_DETALLE!$J$2:$J$194,APU_DETALLE!$B$2:$B$194,$A2,APU_DETALLE!$E$2:$E$194,"Mano Obra") -> 45 | I2: =SUMIFS(APU_DETALLE!$J$2:$J$194,APU_DETALLE!$B$2:$B$194,$A2,APU_DETALLE!$E$2:$E$194,"Subcontrato") -> 0 | J2: =G2+H2+I2 -> 196.68333 | K2: {=G2:G9*$F$2:$F$9} -> 151.68333 | L2: {=H2:H9*$F$2:$F$9} -> 45 | M2: {=I2:I9*$F$2:$F$9} -> 0 | N2: =K2+L2+M2 -> 196.68333
A3: =EDT!A3 -> EDT-PRE-002 | B3: =EDT!B3 -> PRELIMINARES | C3: =EDT!C3 -> SERVICIOS TEMPORALES | D3: =EDT!D3 -> ENERGIA PROVISIONAL | E3: =EDT!E3 -> un | F3: =EDT!F3 -> 1 | G3: =SUMIFS(APU_DETALLE!$J$2:$J$194,APU_DETALLE!$B$2:$B$194,$A3,APU_DETALLE!$E$2:$E$194,"Material") -> 479 | H3: =SUMIFS(APU_DETALLE!$J$2:$J$194,APU_DETALLE!$B$2:$B$194,$A3,APU_DETALLE!$E$2:$E$194,"Mano Obra") -> 50 | I3: =SUMIFS(APU_DETALLE!$J$2:$J$194,APU_DETALLE!$B$2:$B$194,$A3,APU_DETALLE!$E$2:$E$194,"Subcontrato") -> 0 | J3: =G3+H3+I3 -> 529 | K3: 479 | L3: 50 | M3: 0 | N3: =K3+L3+M3 -> 529
A4: =EDT!A4 -> EDT-PRE-003 | B4: =EDT!B4 -> PRELIMINARES | C4: =EDT!C4 -> LIMPIEZA & NIVELACION | D4: =EDT!D4 -> LIMPIEZA & NIVELACION DEL TERRENO | E4: =EDT!E4 -> m2 | F4: =EDT!F4 -> 80 | G4: =SUMIFS(APU_DETALLE!$J$2:$J$194,APU_DETALLE!$B$2:$B$194,$A4,APU_DETALLE!$E$2:$E$194,"Material") -> 0 | H4: =SUMIFS(APU_DETALLE!$J$2:$J$194,APU_DETALLE!$B$2:$B$194,$A4,APU_DETALLE!$E$2:$E$194,"Mano Obra") -> 0 | I4: =SUMIFS(APU_DETALLE!$J$2:$J$194,APU_DETALLE!$B$2:$B$194,$A4,APU_DETALLE!$E$2:$E$194,"Subcontrato") -> 1.44 | J4: =G4+H4+I4 -> 1.44 | K4: 0 | L4: 0 | M4: 115.2 | N4: =K4+L4+M4 -> 115.2
A5: =EDT!A5 -> EDT-PRE-004 | B5: =EDT!B5 -> PRELIMINARES | C5: =EDT!C5 -> BODEGA DE OBRA | D5: =EDT!D5 -> BODEGA DE OBRA | E5: =EDT!E5 -> un | F5: =EDT!F5 -> 1 | G5: =SUMIFS(APU_DETALLE!$J$2:$J$194,APU_DETALLE!$B$2:$B$194,$A5,APU_DETALLE!$E$2:$E$194,"Material") -> 1269.509 | H5: =SUMIFS(APU_DETALLE!$J$2:$J$194,APU_DETALLE!$B$2:$B$194,$A5,APU_DETALLE!$E$2:$E$194,"Mano Obra") -> 60 | I5: =SUMIFS(APU_DETALLE!$J$2:$J$194,APU_DETALLE!$B$2:$B$194,$A5,APU_DETALLE!$E$2:$E$194,"Subcontrato") -> 0 | J5: =G5+H5+I5 -> 1329.509 | K5: 1269.509 | L5: 60 | M5: 0 | N5: =K5+L5+M5 -> 1329.509
A6: =EDT!A6 -> EDT-PRE-005 | B6: =EDT!B6 -> PRELIMINARES | C6: =EDT!C6 -> TRAZADO | D6: =EDT!D6 -> TRAZADO | E6: =EDT!E6 -> ejes | F6: =EDT!F6 -> 8 | G6: =SUMIFS(APU_DETALLE!$J$2:$J$194,APU_DETALLE!$B$2:$B$194,$A6,APU_DETALLE!$E$2:$E$194,"Material") -> 15 | H6: =SUMIFS(APU_DETALLE!$J$2:$J$194,APU_DETALLE!$B$2:$B$194,$A6,APU_DETALLE!$E$2:$E$194,"Mano Obra") -> 9 | I6: =SUMIFS(APU_DETALLE!$J$2:$J$194,APU_DETALLE!$B$2:$B$194,$A6,APU_DETALLE!$E$2:$E$194,"Subcontrato") -> 0 | J6: =G6+H6+I6 -> 24 | K6: 120 | L6: 72 | M6: 0 | N6: =K6+L6+M6 -> 192
A7: =EDT!A7 -> EDT-FUN-001 | B7: =EDT!B7 -> FUNDACIONES | C7: =EDT!C7 -> CIMENTACION | D7: =EDT!D7 -> PLACA CORRIDA | E7: =EDT!E7 -> ml | F7: =EDT!F7 -> 40 | G7: =SUMIFS(APU_DETALLE!$J$2:$J$194,APU_DETALLE!$B$2:$B$194,$A7,APU_DETALLE!$E$2:$E$194,"Material") -> 20.80017 | H7: =SUMIFS(APU_DETALLE!$J$2:$J$194,APU_DETALLE!$B$2:$B$194,$A7,APU_DETALLE!$E$2:$E$194,"Mano Obra") -> 5.62622 | I7: =SUMIFS(APU_DETALLE!$J$2:$J$194,APU_DETALLE!$B$2:$B$194,$A7,APU_DETALLE!$E$2:$E$194,"Subcontrato") -> 8.775 | J7: =G7+H7+I7 -> 35.20139 | K7: 832.0068 | L7: 225.0488 | M7: 351 | N7: =K7+L7+M7 -> 1408.0556
A8: =EDT!A8 -> EDT-FUN-002 | B8: =EDT!B8 -> FUNDACIONES | C8: =EDT!C8 -> CIMENTACION | D8: =EDT!D8 -> SOBRECIMIENTO | E8: =EDT!E8 -> ml | F8: =EDT!F8 -> 40 | G8: =SUMIFS(APU_DETALLE!$J$2:$J$194,APU_DETALLE!$B$2:$B$194,$A8,APU_DETALLE!$E$2:$E$194,"Material") -> 5.68 | H8: =SUMIFS(APU_DETALLE!$J$2:$J$194,APU_DETALLE!$B$2:$B$194,$A8,APU_DETALLE!$E$2:$E$194,"Mano Obra") -> 2.86 | I8: =SUMIFS(APU_DETALLE!$J$2:$J$194,APU_DETALLE!$B$2:$B$194,$A8,APU_DETALLE!$E$2:$E$194,"Subcontrato") -> 0 | J8: =G8+H8+I8 -> 8.54 | K8: 227.2 | L8: 114.4 | M8: 0 | N8: =K8+L8+M8 -> 341.6
K9: 0 | L9: 0 | M9: 0 | N9: =K9+L9+M9 -> 0
A10: TOTAL | G10: =SUM(G2:G9) -> 1941.6725 | H10: =SUM(H2:H9) -> 172.48622 | I10: =SUM(I2:I9) -> 10.215 | J10: =SUM(J2:J9) -> 2124.3737 | K10: =SUM(_xlfn.ANCHORARRAY(K2)) -> 3079.3991 | L10: =SUM(_xlfn.ANCHORARRAY(L2)) -> 566.4488 | M10: =SUM(_xlfn.ANCHORARRAY(M2)) -> 466.2 | N10: =SUM(N2:N9) -> 4112.0479

Sheet CONTROL
A1: Hoja de control / revisión del MVP
A3: Indicador | B3: Valor | C3: Estado | D3: Nota
A4: Actividades EDT | B4: =COUNTA(EDT!$A$2:$A$200) -> 8 | C4: =IF(B4>0,"OK","REVISAR") -> OK | D4: Debe existir catálogo base
A5: Parámetros cargados | B5: =COUNTA(PARAMETROS!$A$2:$A$198) -> 33 | C5: =IF(B5>0,"OK","REVISAR") -> OK | D5: Inputs base del motor
A6: Subactividades PK | B6: =COUNTA(PAQUETE_PK!$C$2:$C$198) -> 23 | C6: =IF(B6>0,"OK","REVISAR") -> OK | D6: Debe coincidir con el paquete diseñado
A7: Líneas de mapeo | B7: =COUNTA(RENDIMIENTOS_BASE!$E$2:$E$200) -> 73 | C7: =IF(B7>0,"OK","REVISAR") -> OK | D7: Explosión de recursos
A8: Filas de APU | B8: =COUNTA(APU_DETALLE!$A$2:$A$194) -> 64 | C8: =IF(B8>0,"OK","REVISAR") -> OK | D8: Detalle costeado
A9: Costo total modelo | B9: =SUMIFS(RESUMEN_EDT!$J$2:$J$206,RESUMEN_EDT!$A$2:$A$206,"<>TOTAL",RESUMEN_EDT!$A$2:$A$206,"<>") -> 2124.3737 | C9: =IF(B9>=0,"OK","REVISAR") -> OK | D9: Total consolidado
A10: Precios unitarios en cero | B10: =COUNTIF(RECURSOS_PRECIOS!$E$2:$E$201,0) -> 0 | C10: =IF(B10=0,"OK","REVISAR") -> OK | D10: Si hay cero, revisar base de precios

Sheet Hoja1
